Workbook

Sheet Maandoverzicht
B2: Maandoverzicht BV
B4: WAT KOMT ER BINNEN (per maand) | C4: EUR | D4: USD
B5: Maandinkomen (kwartaalfactuur ÷ 3) | C5: =IFERROR(ROUND(D5*Parameters!C7,0),0) | D5: =IFERROR(ROUND(Parameters!C6/3,0),0)
B7: WAT MOET OPZIJ (per maand) | C7: EUR | D7: USD
B8: Salaris DGA (bruto, incl. loonheffing) | C8: =Parameters!C10 | D8: =IFERROR(ROUND(C8/Parameters!C7,0),0)
B9: Werkgeversheffing ZVW | C9: =IFERROR(ROUND(Parameters!C10*Parameters!C12,0),0) | D9: =IFERROR(ROUND(C9/Parameters!C7,0),0)
B10: VPB reservering | C10: ='VPB Berekening'!C17 | D10: =IFERROR(ROUND(C10/Parameters!C7,0),0)
B11: Overige BV kosten | C11: =IFERROR(ROUND(Parameters!C28/12,0),0) | D11: =IFERROR(ROUND(C11/Parameters!C7,0),0)
B12: NB: loonheffing zit IN het bruto; BV draagt dit af aan belastingdienst
B14: Totaal opzij leggen | C14: =SUM(C8:C11) | D14: =SUM(D8:D11)
B16: WAT BLIJFT OVER | C16: EUR | D16: USD
B17: Vrij te besteden per maand | C17: =C5-C14 | D17: =D5-D14
B19: DIVIDEND (als je winst uitkeert)
B20: Verwachte jaarwinst na VPB | C20: =IFERROR('VPB Berekening'!C20,0)
B21: Dividendbelasting bij volledige uitkering | C21: =IFERROR(ROUND(C20*Parameters!C34,0),0)
B22: Per maand reserveren voor dividendbelasting | C22: =IFERROR(ROUND(C21/12,0),0) | D22: =IFERROR(ROUND(C22/Parameters!C7,0),0)
B24: Converteer maandelijks het EUR bedrag uit "Totaal opzij" voor salaris + belasting.
B25: De rest kan in USD blijven staan tot je een gunstige koers ziet.
B27: HUIDIGE STAND | C27: EUR | D27: USD
B28: Saldo EUR rekeningen | C28: =Parameters!C41
B29: Saldo USD rekeningen | C29: =IFERROR(D29*Parameters!C7,0) | D29: =Parameters!C42
B30: Totaal nu (EUR) | C30: =C28+C29
B32: EINDE JAAR PROGNOSE | C32: EUR
B33: Huidige maand (1-12) | C33: 3 | D33: ← Pas aan per maand
B34: Resterende maanden dit jaar | C34: =12-C33
B35: Huidig vermogen (EUR) | C35: =C30
B36: Plus: resterende inkomsten | C36: =IFERROR(C5*C34,0)
B37: Minus: salariskosten resterende maanden | C37: =IFERROR((C8+C9)*C34,0) | D37: Bruto + ZVW × resterende mnd
B38: Minus: overige BV kosten resterende maanden | C38: =IFERROR(C11*C34,0)
B39: Minus: VPB nog te betalen | C39: =IFERROR('VPB Berekening'!C15-Parameters!C56,0) | D39: Jaar-VPB minus al betaald
B40: Verwacht vermogen einde jaar | C40: =C35+C36-C37-C38-C39
B41: Waarvan beschikbaar voor dividend | C41: =IFERROR('VPB Berekening'!C20,0)
B42: Waarvan beschikbaar voor dividend | C42: =MIN(C40,IFERROR('VPB Berekening'!C20,0)) | D42: Laagste van: winst na VPB of banksaldo
B43: Na dividendbelasting (26.9%) in je pocket | C43: =IFERROR(ROUND(C42*(1-Parameters!C34),0),0)
B44: VERPLICHTE BELASTING | C44: Jaar | D44: Nog open
B45: VPB | C45: =IFERROR('VPB Berekening'!C15,0) | D45: =IFERROR('VPB Berekening'!C15-Parameters!C56,0)
B46: Totaal verplicht | C46: =C45 | D46: =D45
B48: Verwacht vermogen einde jaar | C48: =C40
B49: Minus: VPB nog te betalen | C49: =D46
B50: Vrij in de BV (na verplichte belasting) | C50: =C48-C49
...

Sheet Parameters
B2: Parameters
B3: Vul alleen de gele cellen in. De rest rekent automatisch.
B5: INKOMEN
B6: Kwartaalfactuur (USD) | C6: 52500
B7: Wisselkoers USD → EUR | C7: 0.875 | D7: ← Vervang met =GOOGLEFINANCE("CURRENCY:USDEUR")
B9: SALARIS DGA
B10: Bruto maandsalaris | C10: 5500 | D10: Min. €5.000/mnd (gebruikelijk loon 2026)
B11: Loonheffing % | C11: 0.3697 | D11: Gecombineerd tarief, vraag je accountant
B12: Werkgeversheffing ZVW % | C12: 0.0668
B14: AFTREKBARE JAARKOSTEN BV | D14: Jaarlijks bedrag
B15: Accountant / boekhouder | C15: 3000
B16: Software & tools | C16: 2000 | D16: Licenties, SaaS, etc.
B17: Kantoor / werkplek | C17: 0 | D17: Huur, thuiswerkplek, internet
B18: Auto van de zaak (lease/afschrijving) | C18: 0 | D18: Maandlease × 12 of afschrijving
B19: Auto bijtelling (correctie) | C19: 0 | D19: Negatief als bijtelling, positief als aftrek
B20: Brandstof / laden | C20: 0
B21: Verzekeringen | C21: 0 | D21: Beroepsaansprakelijkheid, etc.
B22: Telefoon & internet | C22: 0 | D22: Zakelijk deel
B23: Reiskosten (excl. auto) | C23: 0 | D23: OV, vluchten, hotels
B24: Opleidingen & cursussen | C24: 0
B25: Afschrijvingen (overig) | C25: 0 | D25: Laptop, meubilair, etc.
B26: Pensioen (eigen bijdrage BV) | C26: 0 | D26: Indien van toepassing
B27: Overige kosten | C27: 0
B28: Totaal jaarkosten BV | C28: =SUM(C15:C27)
B30: VPB TARIEVEN (pas aan bij wetswijziging)
B31: Grens laag tarief | C31: 200000
B32: Laag tarief | C32: 0.19
B33: Hoog tarief | C33: 0.258
B34: Dividendbelasting (AB-heffing) | C34: 0.269
B36: BANKSALDI (actueel) | C36: Saldo | D36: Valuta
B37: Zakelijke rekening EUR | C37: 0
B38: Spaarrekening EUR | C38: 0
B39: Zakelijke rekening USD | C39: 0
B40: USD spaarrekening | C40: 0
B41: Totaal EUR | C41: =C37+C38
B42: Totaal USD | C42: =C39+C40
B43: USD saldo in EUR (actuele koers) | C43: =IFERROR(C42*C7,0)
B44: Totaal vermogen (EUR) | C44: =C41+C43
B46: REKENING COURANT (DGA ↔ BV)
B47: RC schuld DGA aan BV | C47: 0 | D47: Positief = jij hebt schuld aan BV
...

Sheet VPB Berekening
B2: VPB Berekening
B3: Automatisch berekend vanuit Parameters. Niet aanpassen.
B5: OPBRENGSTEN
B6: Jaaromzet USD | C6: =Parameters!C6*4
B7: Jaaromzet EUR | C7: =IFERROR(C6*Parameters!C7,0)
B9: KOSTEN
B10: Salaris + ZVW (jaar) | C10: =IFERROR(Parameters!C10*12*(1+Parameters!C12),0) | D10: Bruto × 12 × (1 + ZVW%)
B11: Overige BV kosten (jaar) | C11: =Parameters!C28
B13: RESULTAAT
B14: Belastbare winst | C14: =C7-C10-C11
B15: VPB verschuldigd (jaar) | C15: =IF(C14<=0,0,IF(C14<=Parameters!C31,C14*Parameters!C32,Parameters!C31*Parameters!C32+(C14-Parameters!C31)*Parameters!C33))
B16: Effectief tarief | C16: =IFERROR(C15/C14,0)
B17: Per maand reserveren | C17: =IFERROR(ROUND(C15/12,0),0)
B18: Per kwartaal reserveren | C18: =IFERROR(ROUND(C15/4,0),0)
B20: Winst na VPB (beschikbaar voor dividend) | C20: =C14-C15
